2025-04-05 07:33:05,823 - [ERROR] - azen_bot.errors - log_error:117 - ERROR_TYPE:GENERAL_ERROR - MESSAGE:Unexpected error: Conflict: terminated by other getUpdates request; make sure that only one bot instance is running - ADDITIONAL_INFO:Traceback:   File "/home/runner/workspace/.pythonlibs/lib/python3.11/site-packages/telegram/ext/updater.py", line 651, in _network_loop_retry
    if not action_cb():
           ^^^^^^^^^^^
  File "/home/runner/workspace/.pythonlibs/lib/python3.11/site-packages/telegram/ext/updater.py", line 602, in polling_action_cb
    updates = self.bot.get_updates(
              ^^^^^^^^^^^^^^^^^^^^^
  File "/home/runner/workspace/.pythonlibs/lib/python3.11/site-packages/telegram/ext/extbot.py", line 228, in get_updates
    updates = super().get_updates(
              ^^^^^^^^^^^^^^^^^^^^
  File "/home/runner/workspace/.pythonlibs/lib/python3.11/site-packages/telegram/bot.py", line 134, in decorator
    result = func(*args, **kwargs)
             ^^^^^^^^^^^^^^^^^^^^^
  File "/home/runner/workspace/.pythonlibs/lib/python3.11/site-packages/telegram/bot.py", line 3140, in get_updates
    self._post(
  File "/home/runner/workspace/.pythonlibs/lib/python3.11/site-packages/telegram/bot.py", line 299, in _post
    return self.request.post(
           ^^^^^^^^^^^^^^^^^^
  File "/home/runner/workspace/.pythonlibs/lib/python3.11/site-packages/telegram/utils/request.py", line 361, in post
    result = self._request_wrapper(
             ^^^^^^^^^^^^^^^^^^^^^^
  File "/home/runner/workspace/.pythonlibs/lib/python3.11/site-packages/telegram/utils/request.py", line 283, in _request_wrapper
    raise Conflict(message)

2025-04-05 07:33:05,825 - [ERROR] - azen_bot - error_handler:898 - Update None caused error Conflict: terminated by other getUpdates request; make sure that only one bot instance is running
Traceback:   File "/home/runner/workspace/.pythonlibs/lib/python3.11/site-packages/telegram/ext/updater.py", line 651, in _network_loop_retry
    if not action_cb():
           ^^^^^^^^^^^
  File "/home/runner/workspace/.pythonlibs/lib/python3.11/site-packages/telegram/ext/updater.py", line 602, in polling_action_cb
    updates = self.bot.get_updates(
              ^^^^^^^^^^^^^^^^^^^^^
  File "/home/runner/workspace/.pythonlibs/lib/python3.11/site-packages/telegram/ext/extbot.py", line 228, in get_updates
    updates = super().get_updates(
              ^^^^^^^^^^^^^^^^^^^^
  File "/home/runner/workspace/.pythonlibs/lib/python3.11/site-packages/telegram/bot.py", line 134, in decorator
    result = func(*args, **kwargs)
             ^^^^^^^^^^^^^^^^^^^^^
  File "/home/runner/workspace/.pythonlibs/lib/python3.11/site-packages/telegram/bot.py", line 3140, in get_updates
    self._post(
  File "/home/runner/workspace/.pythonlibs/lib/python3.11/site-packages/telegram/bot.py", line 299, in _post
    return self.request.post(
           ^^^^^^^^^^^^^^^^^^
  File "/home/runner/workspace/.pythonlibs/lib/python3.11/site-packages/telegram/utils/request.py", line 361, in post
    result = self._request_wrapper(
             ^^^^^^^^^^^^^^^^^^^^^^
  File "/home/runner/workspace/.pythonlibs/lib/python3.11/site-packages/telegram/utils/request.py", line 283, in _request_wrapper
    raise Conflict(message)

2025-04-05 07:33:09,969 - [ERROR] - azen_bot.errors - log_error:117 - ERROR_TYPE:GENERAL_ERROR - MESSAGE:Unexpected error: Conflict: terminated by other getUpdates request; make sure that only one bot instance is running - ADDITIONAL_INFO:Traceback:   File "/home/runner/workspace/.pythonlibs/lib/python3.11/site-packages/telegram/ext/updater.py", line 651, in _network_loop_retry
    if not action_cb():
           ^^^^^^^^^^^
  File "/home/runner/workspace/.pythonlibs/lib/python3.11/site-packages/telegram/ext/updater.py", line 602, in polling_action_cb
    updates = self.bot.get_updates(
              ^^^^^^^^^^^^^^^^^^^^^
  File "/home/runner/workspace/.pythonlibs/lib/python3.11/site-packages/telegram/ext/extbot.py", line 228, in get_updates
    updates = super().get_updates(
              ^^^^^^^^^^^^^^^^^^^^
  File "/home/runner/workspace/.pythonlibs/lib/python3.11/site-packages/telegram/bot.py", line 134, in decorator
    result = func(*args, **kwargs)
             ^^^^^^^^^^^^^^^^^^^^^
  File "/home/runner/workspace/.pythonlibs/lib/python3.11/site-packages/telegram/bot.py", line 3140, in get_updates
    self._post(
  File "/home/runner/workspace/.pythonlibs/lib/python3.11/site-packages/telegram/bot.py", line 299, in _post
    return self.request.post(
           ^^^^^^^^^^^^^^^^^^
  File "/home/runner/workspace/.pythonlibs/lib/python3.11/site-packages/telegram/utils/request.py", line 361, in post
    result = self._request_wrapper(
             ^^^^^^^^^^^^^^^^^^^^^^
  File "/home/runner/workspace/.pythonlibs/lib/python3.11/site-packages/telegram/utils/request.py", line 283, in _request_wrapper
    raise Conflict(message)

2025-04-05 07:33:09,969 - [ERROR] - azen_bot - error_handler:898 - Update None caused error Conflict: terminated by other getUpdates request; make sure that only one bot instance is running
Traceback:   File "/home/runner/workspace/.pythonlibs/lib/python3.11/site-packages/telegram/ext/updater.py", line 651, in _network_loop_retry
    if not action_cb():
           ^^^^^^^^^^^
  File "/home/runner/workspace/.pythonlibs/lib/python3.11/site-packages/telegram/ext/updater.py", line 602, in polling_action_cb
    updates = self.bot.get_updates(
              ^^^^^^^^^^^^^^^^^^^^^
  File "/home/runner/workspace/.pythonlibs/lib/python3.11/site-packages/telegram/ext/extbot.py", line 228, in get_updates
    updates = super().get_updates(
              ^^^^^^^^^^^^^^^^^^^^
  File "/home/runner/workspace/.pythonlibs/lib/python3.11/site-packages/telegram/bot.py", line 134, in decorator
    result = func(*args, **kwargs)
             ^^^^^^^^^^^^^^^^^^^^^
  File "/home/runner/workspace/.pythonlibs/lib/python3.11/site-packages/telegram/bot.py", line 3140, in get_updates
    self._post(
  File "/home/runner/workspace/.pythonlibs/lib/python3.11/site-packages/telegram/bot.py", line 299, in _post
    return self.request.post(
           ^^^^^^^^^^^^^^^^^^
  File "/home/runner/workspace/.pythonlibs/lib/python3.11/site-packages/telegram/utils/request.py", line 361, in post
    result = self._request_wrapper(
             ^^^^^^^^^^^^^^^^^^^^^^
  File "/home/runner/workspace/.pythonlibs/lib/python3.11/site-packages/telegram/utils/request.py", line 283, in _request_wrapper
    raise Conflict(message)

2025-04-05 07:33:11,113 - [ERROR] - azen_bot.errors - log_error:117 - ERROR_TYPE:GENERAL_ERROR - MESSAGE:Unexpected error: Conflict: terminated by other getUpdates request; make sure that only one bot instance is running - ADDITIONAL_INFO:Traceback:   File "/home/runner/workspace/.pythonlibs/lib/python3.11/site-packages/telegram/ext/updater.py", line 651, in _network_loop_retry
    if not action_cb():
           ^^^^^^^^^^^
  File "/home/runner/workspace/.pythonlibs/lib/python3.11/site-packages/telegram/ext/updater.py", line 602, in polling_action_cb
    updates = self.bot.get_updates(
              ^^^^^^^^^^^^^^^^^^^^^
  File "/home/runner/workspace/.pythonlibs/lib/python3.11/site-packages/telegram/ext/extbot.py", line 228, in get_updates
    updates = super().get_updates(
              ^^^^^^^^^^^^^^^^^^^^
  File "/home/runner/workspace/.pythonlibs/lib/python3.11/site-packages/telegram/bot.py", line 134, in decorator
    result = func(*args, **kwargs)
             ^^^^^^^^^^^^^^^^^^^^^
  File "/home/runner/workspace/.pythonlibs/lib/python3.11/site-packages/telegram/bot.py", line 3140, in get_updates
    self._post(
  File "/home/runner/workspace/.pythonlibs/lib/python3.11/site-packages/telegram/bot.py", line 299, in _post
    return self.request.post(
           ^^^^^^^^^^^^^^^^^^
  File "/home/runner/workspace/.pythonlibs/lib/python3.11/site-packages/telegram/utils/request.py", line 361, in post
    result = self._request_wrapper(
             ^^^^^^^^^^^^^^^^^^^^^^
  File "/home/runner/workspace/.pythonlibs/lib/python3.11/site-packages/telegram/utils/request.py", line 283, in _request_wrapper
    raise Conflict(message)

2025-04-05 07:33:11,113 - [ERROR] - azen_bot - error_handler:898 - Update None caused error Conflict: terminated by other getUpdates request; make sure that only one bot instance is running
Traceback:   File "/home/runner/workspace/.pythonlibs/lib/python3.11/site-packages/telegram/ext/updater.py", line 651, in _network_loop_retry
    if not action_cb():
           ^^^^^^^^^^^
  File "/home/runner/workspace/.pythonlibs/lib/python3.11/site-packages/telegram/ext/updater.py", line 602, in polling_action_cb
    updates = self.bot.get_updates(
              ^^^^^^^^^^^^^^^^^^^^^
  File "/home/runner/workspace/.pythonlibs/lib/python3.11/site-packages/telegram/ext/extbot.py", line 228, in get_updates
    updates = super().get_updates(
              ^^^^^^^^^^^^^^^^^^^^
  File "/home/runner/workspace/.pythonlibs/lib/python3.11/site-packages/telegram/bot.py", line 134, in decorator
    result = func(*args, **kwargs)
             ^^^^^^^^^^^^^^^^^^^^^
  File "/home/runner/workspace/.pythonlibs/lib/python3.11/site-packages/telegram/bot.py", line 3140, in get_updates
    self._post(
  File "/home/runner/workspace/.pythonlibs/lib/python3.11/site-packages/telegram/bot.py", line 299, in _post
    return self.request.post(
           ^^^^^^^^^^^^^^^^^^
  File "/home/runner/workspace/.pythonlibs/lib/python3.11/site-packages/telegram/utils/request.py", line 361, in post
    result = self._request_wrapper(
             ^^^^^^^^^^^^^^^^^^^^^^
  File "/home/runner/workspace/.pythonlibs/lib/python3.11/site-packages/telegram/utils/request.py", line 283, in _request_wrapper
    raise Conflict(message)

2025-04-05 07:33:18,963 - [ERROR] - azen_bot.errors - log_error:117 - ERROR_TYPE:GENERAL_ERROR - MESSAGE:Unexpected error: Conflict: terminated by other getUpdates request; make sure that only one bot instance is running - ADDITIONAL_INFO:Traceback:   File "/home/runner/workspace/.pythonlibs/lib/python3.11/site-packages/telegram/ext/updater.py", line 651, in _network_loop_retry
    if not action_cb():
           ^^^^^^^^^^^
  File "/home/runner/workspace/.pythonlibs/lib/python3.11/site-packages/telegram/ext/updater.py", line 602, in polling_action_cb
    updates = self.bot.get_updates(
              ^^^^^^^^^^^^^^^^^^^^^
  File "/home/runner/workspace/.pythonlibs/lib/python3.11/site-packages/telegram/ext/extbot.py", line 228, in get_updates
    updates = super().get_updates(
              ^^^^^^^^^^^^^^^^^^^^
  File "/home/runner/workspace/.pythonlibs/lib/python3.11/site-packages/telegram/bot.py", line 134, in decorator
    result = func(*args, **kwargs)
             ^^^^^^^^^^^^^^^^^^^^^
  File "/home/runner/workspace/.pythonlibs/lib/python3.11/site-packages/telegram/bot.py", line 3140, in get_updates
    self._post(
  File "/home/runner/workspace/.pythonlibs/lib/python3.11/site-packages/telegram/bot.py", line 299, in _post
    return self.request.post(
           ^^^^^^^^^^^^^^^^^^
  File "/home/runner/workspace/.pythonlibs/lib/python3.11/site-packages/telegram/utils/request.py", line 361, in post
    result = self._request_wrapper(
             ^^^^^^^^^^^^^^^^^^^^^^
  File "/home/runner/workspace/.pythonlibs/lib/python3.11/site-packages/telegram/utils/request.py", line 283, in _request_wrapper
    raise Conflict(message)

2025-04-05 07:33:18,964 - [ERROR] - azen_bot - error_handler:898 - Update None caused error Conflict: terminated by other getUpdates request; make sure that only one bot instance is running
Traceback:   File "/home/runner/workspace/.pythonlibs/lib/python3.11/site-packages/telegram/ext/updater.py", line 651, in _network_loop_retry
    if not action_cb():
           ^^^^^^^^^^^
  File "/home/runner/workspace/.pythonlibs/lib/python3.11/site-packages/telegram/ext/updater.py", line 602, in polling_action_cb
    updates = self.bot.get_updates(
              ^^^^^^^^^^^^^^^^^^^^^
  File "/home/runner/workspace/.pythonlibs/lib/python3.11/site-packages/telegram/ext/extbot.py", line 228, in get_updates
    updates = super().get_updates(
              ^^^^^^^^^^^^^^^^^^^^
  File "/home/runner/workspace/.pythonlibs/lib/python3.11/site-packages/telegram/bot.py", line 134, in decorator
    result = func(*args, **kwargs)
             ^^^^^^^^^^^^^^^^^^^^^
  File "/home/runner/workspace/.pythonlibs/lib/python3.11/site-packages/telegram/bot.py", line 3140, in get_updates
    self._post(
  File "/home/runner/workspace/.pythonlibs/lib/python3.11/site-packages/telegram/bot.py", line 299, in _post
    return self.request.post(
           ^^^^^^^^^^^^^^^^^^
  File "/home/runner/workspace/.pythonlibs/lib/python3.11/site-packages/telegram/utils/request.py", line 361, in post
    result = self._request_wrapper(
             ^^^^^^^^^^^^^^^^^^^^^^
  File "/home/runner/workspace/.pythonlibs/lib/python3.11/site-packages/telegram/utils/request.py", line 283, in _request_wrapper
    raise Conflict(message)

2025-04-05 07:33:24,366 - [ERROR] - azen_bot.errors - log_error:117 - ERROR_TYPE:GENERAL_ERROR - MESSAGE:Unexpected error: Conflict: terminated by other getUpdates request; make sure that only one bot instance is running - ADDITIONAL_INFO:Traceback:   File "/home/runner/workspace/.pythonlibs/lib/python3.11/site-packages/telegram/ext/updater.py", line 651, in _network_loop_retry
    if not action_cb():
           ^^^^^^^^^^^
  File "/home/runner/workspace/.pythonlibs/lib/python3.11/site-packages/telegram/ext/updater.py", line 602, in polling_action_cb
    updates = self.bot.get_updates(
              ^^^^^^^^^^^^^^^^^^^^^
  File "/home/runner/workspace/.pythonlibs/lib/python3.11/site-packages/telegram/ext/extbot.py", line 228, in get_updates
    updates = super().get_updates(
              ^^^^^^^^^^^^^^^^^^^^
  File "/home/runner/workspace/.pythonlibs/lib/python3.11/site-packages/telegram/bot.py", line 134, in decorator
    result = func(*args, **kwargs)
             ^^^^^^^^^^^^^^^^^^^^^
  File "/home/runner/workspace/.pythonlibs/lib/python3.11/site-packages/telegram/bot.py", line 3140, in get_updates
    self._post(
  File "/home/runner/workspace/.pythonlibs/lib/python3.11/site-packages/telegram/bot.py", line 299, in _post
    return self.request.post(
           ^^^^^^^^^^^^^^^^^^
  File "/home/runner/workspace/.pythonlibs/lib/python3.11/site-packages/telegram/utils/request.py", line 361, in post
    result = self._request_wrapper(
             ^^^^^^^^^^^^^^^^^^^^^^
  File "/home/runner/workspace/.pythonlibs/lib/python3.11/site-packages/telegram/utils/request.py", line 283, in _request_wrapper
    raise Conflict(message)

2025-04-05 07:33:24,366 - [ERROR] - azen_bot - error_handler:898 - Update None caused error Conflict: terminated by other getUpdates request; make sure that only one bot instance is running
Traceback:   File "/home/runner/workspace/.pythonlibs/lib/python3.11/site-packages/telegram/ext/updater.py", line 651, in _network_loop_retry
    if not action_cb():
           ^^^^^^^^^^^
  File "/home/runner/workspace/.pythonlibs/lib/python3.11/site-packages/telegram/ext/updater.py", line 602, in polling_action_cb
    updates = self.bot.get_updates(
              ^^^^^^^^^^^^^^^^^^^^^
  File "/home/runner/workspace/.pythonlibs/lib/python3.11/site-packages/telegram/ext/extbot.py", line 228, in get_updates
    updates = super().get_updates(
              ^^^^^^^^^^^^^^^^^^^^
  File "/home/runner/workspace/.pythonlibs/lib/python3.11/site-packages/telegram/bot.py", line 134, in decorator
    result = func(*args, **kwargs)
             ^^^^^^^^^^^^^^^^^^^^^
  File "/home/runner/workspace/.pythonlibs/lib/python3.11/site-packages/telegram/bot.py", line 3140, in get_updates
    self._post(
  File "/home/runner/workspace/.pythonlibs/lib/python3.11/site-packages/telegram/bot.py", line 299, in _post
    return self.request.post(
           ^^^^^^^^^^^^^^^^^^
  File "/home/runner/workspace/.pythonlibs/lib/python3.11/site-packages/telegram/utils/request.py", line 361, in post
    result = self._request_wrapper(
             ^^^^^^^^^^^^^^^^^^^^^^
  File "/home/runner/workspace/.pythonlibs/lib/python3.11/site-packages/telegram/utils/request.py", line 283, in _request_wrapper
    raise Conflict(message)

2025-04-05 07:33:25,510 - [ERROR] - azen_bot.errors - log_error:117 - ERROR_TYPE:GENERAL_ERROR - MESSAGE:Unexpected error: Conflict: terminated by other getUpdates request; make sure that only one bot instance is running - ADDITIONAL_INFO:Traceback:   File "/home/runner/workspace/.pythonlibs/lib/python3.11/site-packages/telegram/ext/updater.py", line 651, in _network_loop_retry
    if not action_cb():
           ^^^^^^^^^^^
  File "/home/runner/workspace/.pythonlibs/lib/python3.11/site-packages/telegram/ext/updater.py", line 602, in polling_action_cb
    updates = self.bot.get_updates(
              ^^^^^^^^^^^^^^^^^^^^^
  File "/home/runner/workspace/.pythonlibs/lib/python3.11/site-packages/telegram/ext/extbot.py", line 228, in get_updates
    updates = super().get_updates(
              ^^^^^^^^^^^^^^^^^^^^
  File "/home/runner/workspace/.pythonlibs/lib/python3.11/site-packages/telegram/bot.py", line 134, in decorator
    result = func(*args, **kwargs)
             ^^^^^^^^^^^^^^^^^^^^^
  File "/home/runner/workspace/.pythonlibs/lib/python3.11/site-packages/telegram/bot.py", line 3140, in get_updates
    self._post(
  File "/home/runner/workspace/.pythonlibs/lib/python3.11/site-packages/telegram/bot.py", line 299, in _post
    return self.request.post(
           ^^^^^^^^^^^^^^^^^^
  File "/home/runner/workspace/.pythonlibs/lib/python3.11/site-packages/telegram/utils/request.py", line 361, in post
    result = self._request_wrapper(
             ^^^^^^^^^^^^^^^^^^^^^^
  File "/home/runner/workspace/.pythonlibs/lib/python3.11/site-packages/telegram/utils/request.py", line 283, in _request_wrapper
    raise Conflict(message)

2025-04-05 07:33:25,510 - [ERROR] - azen_bot - error_handler:898 - Update None caused error Conflict: terminated by other getUpdates request; make sure that only one bot instance is running
Traceback:   File "/home/runner/workspace/.pythonlibs/lib/python3.11/site-packages/telegram/ext/updater.py", line 651, in _network_loop_retry
    if not action_cb():
           ^^^^^^^^^^^
  File "/home/runner/workspace/.pythonlibs/lib/python3.11/site-packages/telegram/ext/updater.py", line 602, in polling_action_cb
    updates = self.bot.get_updates(
              ^^^^^^^^^^^^^^^^^^^^^
  File "/home/runner/workspace/.pythonlibs/lib/python3.11/site-packages/telegram/ext/extbot.py", line 228, in get_updates
    updates = super().get_updates(
              ^^^^^^^^^^^^^^^^^^^^
  File "/home/runner/workspace/.pythonlibs/lib/python3.11/site-packages/telegram/bot.py", line 134, in decorator
    result = func(*args, **kwargs)
             ^^^^^^^^^^^^^^^^^^^^^
  File "/home/runner/workspace/.pythonlibs/lib/python3.11/site-packages/telegram/bot.py", line 3140, in get_updates
    self._post(
  File "/home/runner/workspace/.pythonlibs/lib/python3.11/site-packages/telegram/bot.py", line 299, in _post
    return self.request.post(
           ^^^^^^^^^^^^^^^^^^
  File "/home/runner/workspace/.pythonlibs/lib/python3.11/site-packages/telegram/utils/request.py", line 361, in post
    result = self._request_wrapper(
             ^^^^^^^^^^^^^^^^^^^^^^
  File "/home/runner/workspace/.pythonlibs/lib/python3.11/site-packages/telegram/utils/request.py", line 283, in _request_wrapper
    raise Conflict(message)

2025-04-05 07:33:29,030 - [ERROR] - azen_bot.errors - log_error:117 - ERROR_TYPE:GENERAL_ERROR - MESSAGE:Unexpected error: Conflict: terminated by other getUpdates request; make sure that only one bot instance is running - ADDITIONAL_INFO:Traceback:   File "/home/runner/workspace/.pythonlibs/lib/python3.11/site-packages/telegram/ext/updater.py", line 651, in _network_loop_retry
    if not action_cb():
           ^^^^^^^^^^^
  File "/home/runner/workspace/.pythonlibs/lib/python3.11/site-packages/telegram/ext/updater.py", line 602, in polling_action_cb
    updates = self.bot.get_updates(
              ^^^^^^^^^^^^^^^^^^^^^
  File "/home/runner/workspace/.pythonlibs/lib/python3.11/site-packages/telegram/ext/extbot.py", line 228, in get_updates
    updates = super().get_updates(
              ^^^^^^^^^^^^^^^^^^^^
  File "/home/runner/workspace/.pythonlibs/lib/python3.11/site-packages/telegram/bot.py", line 134, in decorator
    result = func(*args, **kwargs)
             ^^^^^^^^^^^^^^^^^^^^^
  File "/home/runner/workspace/.pythonlibs/lib/python3.11/site-packages/telegram/bot.py", line 3140, in get_updates
    self._post(
  File "/home/runner/workspace/.pythonlibs/lib/python3.11/site-packages/telegram/bot.py", line 299, in _post
    return self.request.post(
           ^^^^^^^^^^^^^^^^^^
  File "/home/runner/workspace/.pythonlibs/lib/python3.11/site-packages/telegram/utils/request.py", line 361, in post
    result = self._request_wrapper(
             ^^^^^^^^^^^^^^^^^^^^^^
  File "/home/runner/workspace/.pythonlibs/lib/python3.11/site-packages/telegram/utils/request.py", line 283, in _request_wrapper
    raise Conflict(message)

2025-04-05 07:33:29,031 - [ERROR] - azen_bot - error_handler:898 - Update None caused error Conflict: terminated by other getUpdates request; make sure that only one bot instance is running
Traceback:   File "/home/runner/workspace/.pythonlibs/lib/python3.11/site-packages/telegram/ext/updater.py", line 651, in _network_loop_retry
    if not action_cb():
           ^^^^^^^^^^^
  File "/home/runner/workspace/.pythonlibs/lib/python3.11/site-packages/telegram/ext/updater.py", line 602, in polling_action_cb
    updates = self.bot.get_updates(
              ^^^^^^^^^^^^^^^^^^^^^
  File "/home/runner/workspace/.pythonlibs/lib/python3.11/site-packages/telegram/ext/extbot.py", line 228, in get_updates
    updates = super().get_updates(
              ^^^^^^^^^^^^^^^^^^^^
  File "/home/runner/workspace/.pythonlibs/lib/python3.11/site-packages/telegram/bot.py", line 134, in decorator
    result = func(*args, **kwargs)
             ^^^^^^^^^^^^^^^^^^^^^
  File "/home/runner/workspace/.pythonlibs/lib/python3.11/site-packages/telegram/bot.py", line 3140, in get_updates
    self._post(
  File "/home/runner/workspace/.pythonlibs/lib/python3.11/site-packages/telegram/bot.py", line 299, in _post
    return self.request.post(
           ^^^^^^^^^^^^^^^^^^
  File "/home/runner/workspace/.pythonlibs/lib/python3.11/site-packages/telegram/utils/request.py", line 361, in post
    result = self._request_wrapper(
             ^^^^^^^^^^^^^^^^^^^^^^
  File "/home/runner/workspace/.pythonlibs/lib/python3.11/site-packages/telegram/utils/request.py", line 283, in _request_wrapper
    raise Conflict(message)

2025-04-05 07:33:33,674 - [ERROR] - azen_bot.errors - log_error:117 - ERROR_TYPE:GENERAL_ERROR - MESSAGE:Unexpected error: Conflict: terminated by other getUpdates request; make sure that only one bot instance is running - ADDITIONAL_INFO:Traceback:   File "/home/runner/workspace/.pythonlibs/lib/python3.11/site-packages/telegram/ext/updater.py", line 651, in _network_loop_retry
    if not action_cb():
           ^^^^^^^^^^^
  File "/home/runner/workspace/.pythonlibs/lib/python3.11/site-packages/telegram/ext/updater.py", line 602, in polling_action_cb
    updates = self.bot.get_updates(
              ^^^^^^^^^^^^^^^^^^^^^
  File "/home/runner/workspace/.pythonlibs/lib/python3.11/site-packages/telegram/ext/extbot.py", line 228, in get_updates
    updates = super().get_updates(
              ^^^^^^^^^^^^^^^^^^^^
  File "/home/runner/workspace/.pythonlibs/lib/python3.11/site-packages/telegram/bot.py", line 134, in decorator
    result = func(*args, **kwargs)
             ^^^^^^^^^^^^^^^^^^^^^
  File "/home/runner/workspace/.pythonlibs/lib/python3.11/site-packages/telegram/bot.py", line 3140, in get_updates
    self._post(
  File "/home/runner/workspace/.pythonlibs/lib/python3.11/site-packages/telegram/bot.py", line 299, in _post
    return self.request.post(
           ^^^^^^^^^^^^^^^^^^
  File "/home/runner/workspace/.pythonlibs/lib/python3.11/site-packages/telegram/utils/request.py", line 361, in post
    result = self._request_wrapper(
             ^^^^^^^^^^^^^^^^^^^^^^
  File "/home/runner/workspace/.pythonlibs/lib/python3.11/site-packages/telegram/utils/request.py", line 283, in _request_wrapper
    raise Conflict(message)

2025-04-05 07:33:33,674 - [ERROR] - azen_bot - error_handler:898 - Update None caused error Conflict: terminated by other getUpdates request; make sure that only one bot instance is running
Traceback:   File "/home/runner/workspace/.pythonlibs/lib/python3.11/site-packages/telegram/ext/updater.py", line 651, in _network_loop_retry
    if not action_cb():
           ^^^^^^^^^^^
  File "/home/runner/workspace/.pythonlibs/lib/python3.11/site-packages/telegram/ext/updater.py", line 602, in polling_action_cb
    updates = self.bot.get_updates(
              ^^^^^^^^^^^^^^^^^^^^^
  File "/home/runner/workspace/.pythonlibs/lib/python3.11/site-packages/telegram/ext/extbot.py", line 228, in get_updates
    updates = super().get_updates(
              ^^^^^^^^^^^^^^^^^^^^
  File "/home/runner/workspace/.pythonlibs/lib/python3.11/site-packages/telegram/bot.py", line 134, in decorator
    result = func(*args, **kwargs)
             ^^^^^^^^^^^^^^^^^^^^^
  File "/home/runner/workspace/.pythonlibs/lib/python3.11/site-packages/telegram/bot.py", line 3140, in get_updates
    self._post(
  File "/home/runner/workspace/.pythonlibs/lib/python3.11/site-packages/telegram/bot.py", line 299, in _post
    return self.request.post(
           ^^^^^^^^^^^^^^^^^^
  File "/home/runner/workspace/.pythonlibs/lib/python3.11/site-packages/telegram/utils/request.py", line 361, in post
    result = self._request_wrapper(
             ^^^^^^^^^^^^^^^^^^^^^^
  File "/home/runner/workspace/.pythonlibs/lib/python3.11/site-packages/telegram/utils/request.py", line 283, in _request_wrapper
    raise Conflict(message)

2025-04-05 07:33:38,883 - [ERROR] - azen_bot.errors - log_error:117 - ERROR_TYPE:GENERAL_ERROR - MESSAGE:Unexpected error: Conflict: terminated by other getUpdates request; make sure that only one bot instance is running - ADDITIONAL_INFO:Traceback:   File "/home/runner/workspace/.pythonlibs/lib/python3.11/site-packages/telegram/ext/updater.py", line 651, in _network_loop_retry
    if not action_cb():
           ^^^^^^^^^^^
  File "/home/runner/workspace/.pythonlibs/lib/python3.11/site-packages/telegram/ext/updater.py", line 602, in polling_action_cb
    updates = self.bot.get_updates(
              ^^^^^^^^^^^^^^^^^^^^^
  File "/home/runner/workspace/.pythonlibs/lib/python3.11/site-packages/telegram/ext/extbot.py", line 228, in get_updates
    updates = super().get_updates(
              ^^^^^^^^^^^^^^^^^^^^
  File "/home/runner/workspace/.pythonlibs/lib/python3.11/site-packages/telegram/bot.py", line 134, in decorator
    result = func(*args, **kwargs)
             ^^^^^^^^^^^^^^^^^^^^^
  File "/home/runner/workspace/.pythonlibs/lib/python3.11/site-packages/telegram/bot.py", line 3140, in get_updates
    self._post(
  File "/home/runner/workspace/.pythonlibs/lib/python3.11/site-packages/telegram/bot.py", line 299, in _post
    return self.request.post(
           ^^^^^^^^^^^^^^^^^^
  File "/home/runner/workspace/.pythonlibs/lib/python3.11/site-packages/telegram/utils/request.py", line 361, in post
    result = self._request_wrapper(
             ^^^^^^^^^^^^^^^^^^^^^^
  File "/home/runner/workspace/.pythonlibs/lib/python3.11/site-packages/telegram/utils/request.py", line 283, in _request_wrapper
    raise Conflict(message)

2025-04-05 07:33:38,883 - [ERROR] - azen_bot - error_handler:898 - Update None caused error Conflict: terminated by other getUpdates request; make sure that only one bot instance is running
Traceback:   File "/home/runner/workspace/.pythonlibs/lib/python3.11/site-packages/telegram/ext/updater.py", line 651, in _network_loop_retry
    if not action_cb():
           ^^^^^^^^^^^
  File "/home/runner/workspace/.pythonlibs/lib/python3.11/site-packages/telegram/ext/updater.py", line 602, in polling_action_cb
    updates = self.bot.get_updates(
              ^^^^^^^^^^^^^^^^^^^^^
  File "/home/runner/workspace/.pythonlibs/lib/python3.11/site-packages/telegram/ext/extbot.py", line 228, in get_updates
    updates = super().get_updates(
              ^^^^^^^^^^^^^^^^^^^^
  File "/home/runner/workspace/.pythonlibs/lib/python3.11/site-packages/telegram/bot.py", line 134, in decorator
    result = func(*args, **kwargs)
             ^^^^^^^^^^^^^^^^^^^^^
  File "/home/runner/workspace/.pythonlibs/lib/python3.11/site-packages/telegram/bot.py", line 3140, in get_updates
    self._post(
  File "/home/runner/workspace/.pythonlibs/lib/python3.11/site-packages/telegram/bot.py", line 299, in _post
    return self.request.post(
           ^^^^^^^^^^^^^^^^^^
  File "/home/runner/workspace/.pythonlibs/lib/python3.11/site-packages/telegram/utils/request.py", line 361, in post
    result = self._request_wrapper(
             ^^^^^^^^^^^^^^^^^^^^^^
  File "/home/runner/workspace/.pythonlibs/lib/python3.11/site-packages/telegram/utils/request.py", line 283, in _request_wrapper
    raise Conflict(message)

2025-04-05 07:33:44,275 - [ERROR] - azen_bot.errors - log_error:117 - ERROR_TYPE:GENERAL_ERROR - MESSAGE:Unexpected error: Conflict: terminated by other getUpdates request; make sure that only one bot instance is running - ADDITIONAL_INFO:Traceback:   File "/home/runner/workspace/.pythonlibs/lib/python3.11/site-packages/telegram/ext/updater.py", line 651, in _network_loop_retry
    if not action_cb():
           ^^^^^^^^^^^
  File "/home/runner/workspace/.pythonlibs/lib/python3.11/site-packages/telegram/ext/updater.py", line 602, in polling_action_cb
    updates = self.bot.get_updates(
              ^^^^^^^^^^^^^^^^^^^^^
  File "/home/runner/workspace/.pythonlibs/lib/python3.11/site-packages/telegram/ext/extbot.py", line 228, in get_updates
    updates = super().get_updates(
              ^^^^^^^^^^^^^^^^^^^^
  File "/home/runner/workspace/.pythonlibs/lib/python3.11/site-packages/telegram/bot.py", line 134, in decorator
    result = func(*args, **kwargs)
             ^^^^^^^^^^^^^^^^^^^^^
  File "/home/runner/workspace/.pythonlibs/lib/python3.11/site-packages/telegram/bot.py", line 3140, in get_updates
    self._post(
  File "/home/runner/workspace/.pythonlibs/lib/python3.11/site-packages/telegram/bot.py", line 299, in _post
    return self.request.post(
           ^^^^^^^^^^^^^^^^^^
  File "/home/runner/workspace/.pythonlibs/lib/python3.11/site-packages/telegram/utils/request.py", line 361, in post
    result = self._request_wrapper(
             ^^^^^^^^^^^^^^^^^^^^^^
  File "/home/runner/workspace/.pythonlibs/lib/python3.11/site-packages/telegram/utils/request.py", line 283, in _request_wrapper
    raise Conflict(message)

2025-04-05 07:33:44,276 - [ERROR] - azen_bot - error_handler:898 - Update None caused error Conflict: terminated by other getUpdates request; make sure that only one bot instance is running
Traceback:   File "/home/runner/workspace/.pythonlibs/lib/python3.11/site-packages/telegram/ext/updater.py", line 651, in _network_loop_retry
    if not action_cb():
           ^^^^^^^^^^^
  File "/home/runner/workspace/.pythonlibs/lib/python3.11/site-packages/telegram/ext/updater.py", line 602, in polling_action_cb
    updates = self.bot.get_updates(
              ^^^^^^^^^^^^^^^^^^^^^
  File "/home/runner/workspace/.pythonlibs/lib/python3.11/site-packages/telegram/ext/extbot.py", line 228, in get_updates
    updates = super().get_updates(
              ^^^^^^^^^^^^^^^^^^^^
  File "/home/runner/workspace/.pythonlibs/lib/python3.11/site-packages/telegram/bot.py", line 134, in decorator
    result = func(*args, **kwargs)
             ^^^^^^^^^^^^^^^^^^^^^
  File "/home/runner/workspace/.pythonlibs/lib/python3.11/site-packages/telegram/bot.py", line 3140, in get_updates
    self._post(
  File "/home/runner/workspace/.pythonlibs/lib/python3.11/site-packages/telegram/bot.py", line 299, in _post
    return self.request.post(
           ^^^^^^^^^^^^^^^^^^
  File "/home/runner/workspace/.pythonlibs/lib/python3.11/site-packages/telegram/utils/request.py", line 361, in post
    result = self._request_wrapper(
             ^^^^^^^^^^^^^^^^^^^^^^
  File "/home/runner/workspace/.pythonlibs/lib/python3.11/site-packages/telegram/utils/request.py", line 283, in _request_wrapper
    raise Conflict(message)

2025-04-05 07:33:52,016 - [ERROR] - azen_bot.errors - log_error:117 - ERROR_TYPE:GENERAL_ERROR - MESSAGE:Unexpected error: Conflict: terminated by other getUpdates request; make sure that only one bot instance is running - ADDITIONAL_INFO:Traceback:   File "/home/runner/workspace/.pythonlibs/lib/python3.11/site-packages/telegram/ext/updater.py", line 651, in _network_loop_retry
    if not action_cb():
           ^^^^^^^^^^^
  File "/home/runner/workspace/.pythonlibs/lib/python3.11/site-packages/telegram/ext/updater.py", line 602, in polling_action_cb
    updates = self.bot.get_updates(
              ^^^^^^^^^^^^^^^^^^^^^
  File "/home/runner/workspace/.pythonlibs/lib/python3.11/site-packages/telegram/ext/extbot.py", line 228, in get_updates
    updates = super().get_updates(
              ^^^^^^^^^^^^^^^^^^^^
  File "/home/runner/workspace/.pythonlibs/lib/python3.11/site-packages/telegram/bot.py", line 134, in decorator
    result = func(*args, **kwargs)
             ^^^^^^^^^^^^^^^^^^^^^
  File "/home/runner/workspace/.pythonlibs/lib/python3.11/site-packages/telegram/bot.py", line 3140, in get_updates
    self._post(
  File "/home/runner/workspace/.pythonlibs/lib/python3.11/site-packages/telegram/bot.py", line 299, in _post
    return self.request.post(
           ^^^^^^^^^^^^^^^^^^
  File "/home/runner/workspace/.pythonlibs/lib/python3.11/site-packages/telegram/utils/request.py", line 361, in post
    result = self._request_wrapper(
             ^^^^^^^^^^^^^^^^^^^^^^
  File "/home/runner/workspace/.pythonlibs/lib/python3.11/site-packages/telegram/utils/request.py", line 283, in _request_wrapper
    raise Conflict(message)

2025-04-05 07:33:52,016 - [ERROR] - azen_bot - error_handler:898 - Update None caused error Conflict: terminated by other getUpdates request; make sure that only one bot instance is running
Traceback:   File "/home/runner/workspace/.pythonlibs/lib/python3.11/site-packages/telegram/ext/updater.py", line 651, in _network_loop_retry
    if not action_cb():
           ^^^^^^^^^^^
  File "/home/runner/workspace/.pythonlibs/lib/python3.11/site-packages/telegram/ext/updater.py", line 602, in polling_action_cb
    updates = self.bot.get_updates(
              ^^^^^^^^^^^^^^^^^^^^^
  File "/home/runner/workspace/.pythonlibs/lib/python3.11/site-packages/telegram/ext/extbot.py", line 228, in get_updates
    updates = super().get_updates(
              ^^^^^^^^^^^^^^^^^^^^
  File "/home/runner/workspace/.pythonlibs/lib/python3.11/site-packages/telegram/bot.py", line 134, in decorator
    result = func(*args, **kwargs)
             ^^^^^^^^^^^^^^^^^^^^^
  File "/home/runner/workspace/.pythonlibs/lib/python3.11/site-packages/telegram/bot.py", line 3140, in get_updates
    self._post(
  File "/home/runner/workspace/.pythonlibs/lib/python3.11/site-packages/telegram/bot.py", line 299, in _post
    return self.request.post(
           ^^^^^^^^^^^^^^^^^^
  File "/home/runner/workspace/.pythonlibs/lib/python3.11/site-packages/telegram/utils/request.py", line 361, in post
    result = self._request_wrapper(
             ^^^^^^^^^^^^^^^^^^^^^^
  File "/home/runner/workspace/.pythonlibs/lib/python3.11/site-packages/telegram/utils/request.py", line 283, in _request_wrapper
    raise Conflict(message)

2025-04-05 07:33:56,159 - [ERROR] - azen_bot.errors - log_error:117 - ERROR_TYPE:GENERAL_ERROR - MESSAGE:Unexpected error: Conflict: terminated by other getUpdates request; make sure that only one bot instance is running - ADDITIONAL_INFO:Traceback:   File "/home/runner/workspace/.pythonlibs/lib/python3.11/site-packages/telegram/ext/updater.py", line 651, in _network_loop_retry
    if not action_cb():
           ^^^^^^^^^^^
  File "/home/runner/workspace/.pythonlibs/lib/python3.11/site-packages/telegram/ext/updater.py", line 602, in polling_action_cb
    updates = self.bot.get_updates(
              ^^^^^^^^^^^^^^^^^^^^^
  File "/home/runner/workspace/.pythonlibs/lib/python3.11/site-packages/telegram/ext/extbot.py", line 228, in get_updates
    updates = super().get_updates(
              ^^^^^^^^^^^^^^^^^^^^
  File "/home/runner/workspace/.pythonlibs/lib/python3.11/site-packages/telegram/bot.py", line 134, in decorator
    result = func(*args, **kwargs)
             ^^^^^^^^^^^^^^^^^^^^^
  File "/home/runner/workspace/.pythonlibs/lib/python3.11/site-packages/telegram/bot.py", line 3140, in get_updates
    self._post(
  File "/home/runner/workspace/.pythonlibs/lib/python3.11/site-packages/telegram/bot.py", line 299, in _post
    return self.request.post(
           ^^^^^^^^^^^^^^^^^^
  File "/home/runner/workspace/.pythonlibs/lib/python3.11/site-packages/telegram/utils/request.py", line 361, in post
    result = self._request_wrapper(
             ^^^^^^^^^^^^^^^^^^^^^^
  File "/home/runner/workspace/.pythonlibs/lib/python3.11/site-packages/telegram/utils/request.py", line 283, in _request_wrapper
    raise Conflict(message)

2025-04-05 07:33:56,159 - [ERROR] - azen_bot - error_handler:898 - Update None caused error Conflict: terminated by other getUpdates request; make sure that only one bot instance is running
Traceback:   File "/home/runner/workspace/.pythonlibs/lib/python3.11/site-packages/telegram/ext/updater.py", line 651, in _network_loop_retry
    if not action_cb():
           ^^^^^^^^^^^
  File "/home/runner/workspace/.pythonlibs/lib/python3.11/site-packages/telegram/ext/updater.py", line 602, in polling_action_cb
    updates = self.bot.get_updates(
              ^^^^^^^^^^^^^^^^^^^^^
  File "/home/runner/workspace/.pythonlibs/lib/python3.11/site-packages/telegram/ext/extbot.py", line 228, in get_updates
    updates = super().get_updates(
              ^^^^^^^^^^^^^^^^^^^^
  File "/home/runner/workspace/.pythonlibs/lib/python3.11/site-packages/telegram/bot.py", line 134, in decorator
    result = func(*args, **kwargs)
             ^^^^^^^^^^^^^^^^^^^^^
  File "/home/runner/workspace/.pythonlibs/lib/python3.11/site-packages/telegram/bot.py", line 3140, in get_updates
    self._post(
  File "/home/runner/workspace/.pythonlibs/lib/python3.11/site-packages/telegram/bot.py", line 299, in _post
    return self.request.post(
           ^^^^^^^^^^^^^^^^^^
  File "/home/runner/workspace/.pythonlibs/lib/python3.11/site-packages/telegram/utils/request.py", line 361, in post
    result = self._request_wrapper(
             ^^^^^^^^^^^^^^^^^^^^^^
  File "/home/runner/workspace/.pythonlibs/lib/python3.11/site-packages/telegram/utils/request.py", line 283, in _request_wrapper
    raise Conflict(message)

2025-04-05 07:34:07,694 - [ERROR] - azen_bot.errors - log_error:117 - ERROR_TYPE:GENERAL_ERROR - MESSAGE:Unexpected error: Conflict: terminated by other getUpdates request; make sure that only one bot instance is running - ADDITIONAL_INFO:Traceback:   File "/home/runner/workspace/.pythonlibs/lib/python3.11/site-packages/telegram/ext/updater.py", line 651, in _network_loop_retry
    if not action_cb():
           ^^^^^^^^^^^
  File "/home/runner/workspace/.pythonlibs/lib/python3.11/site-packages/telegram/ext/updater.py", line 602, in polling_action_cb
    updates = self.bot.get_updates(
              ^^^^^^^^^^^^^^^^^^^^^
  File "/home/runner/workspace/.pythonlibs/lib/python3.11/site-packages/telegram/ext/extbot.py", line 228, in get_updates
    updates = super().get_updates(
              ^^^^^^^^^^^^^^^^^^^^
  File "/home/runner/workspace/.pythonlibs/lib/python3.11/site-packages/telegram/bot.py", line 134, in decorator
    result = func(*args, **kwargs)
             ^^^^^^^^^^^^^^^^^^^^^
  File "/home/runner/workspace/.pythonlibs/lib/python3.11/site-packages/telegram/bot.py", line 3140, in get_updates
    self._post(
  File "/home/runner/workspace/.pythonlibs/lib/python3.11/site-packages/telegram/bot.py", line 299, in _post
    return self.request.post(
           ^^^^^^^^^^^^^^^^^^
  File "/home/runner/workspace/.pythonlibs/lib/python3.11/site-packages/telegram/utils/request.py", line 361, in post
    result = self._request_wrapper(
             ^^^^^^^^^^^^^^^^^^^^^^
  File "/home/runner/workspace/.pythonlibs/lib/python3.11/site-packages/telegram/utils/request.py", line 283, in _request_wrapper
    raise Conflict(message)

2025-04-05 07:34:07,695 - [ERROR] - azen_bot - error_handler:898 - Update None caused error Conflict: terminated by other getUpdates request; make sure that only one bot instance is running
Traceback:   File "/home/runner/workspace/.pythonlibs/lib/python3.11/site-packages/telegram/ext/updater.py", line 651, in _network_loop_retry
    if not action_cb():
           ^^^^^^^^^^^
  File "/home/runner/workspace/.pythonlibs/lib/python3.11/site-packages/telegram/ext/updater.py", line 602, in polling_action_cb
    updates = self.bot.get_updates(
              ^^^^^^^^^^^^^^^^^^^^^
  File "/home/runner/workspace/.pythonlibs/lib/python3.11/site-packages/telegram/ext/extbot.py", line 228, in get_updates
    updates = super().get_updates(
              ^^^^^^^^^^^^^^^^^^^^
  File "/home/runner/workspace/.pythonlibs/lib/python3.11/site-packages/telegram/bot.py", line 134, in decorator
    result = func(*args, **kwargs)
             ^^^^^^^^^^^^^^^^^^^^^
  File "/home/runner/workspace/.pythonlibs/lib/python3.11/site-packages/telegram/bot.py", line 3140, in get_updates
    self._post(
  File "/home/runner/workspace/.pythonlibs/lib/python3.11/site-packages/telegram/bot.py", line 299, in _post
    return self.request.post(
           ^^^^^^^^^^^^^^^^^^
  File "/home/runner/workspace/.pythonlibs/lib/python3.11/site-packages/telegram/utils/request.py", line 361, in post
    result = self._request_wrapper(
             ^^^^^^^^^^^^^^^^^^^^^^
  File "/home/runner/workspace/.pythonlibs/lib/python3.11/site-packages/telegram/utils/request.py", line 283, in _request_wrapper
    raise Conflict(message)

2025-04-05 07:34:11,842 - [ERROR] - azen_bot.errors - log_error:117 - ERROR_TYPE:GENERAL_ERROR - MESSAGE:Unexpected error: Conflict: terminated by other getUpdates request; make sure that only one bot instance is running - ADDITIONAL_INFO:Traceback:   File "/home/runner/workspace/.pythonlibs/lib/python3.11/site-packages/telegram/ext/updater.py", line 651, in _network_loop_retry
    if not action_cb():
           ^^^^^^^^^^^
  File "/home/runner/workspace/.pythonlibs/lib/python3.11/site-packages/telegram/ext/updater.py", line 602, in polling_action_cb
    updates = self.bot.get_updates(
              ^^^^^^^^^^^^^^^^^^^^^
  File "/home/runner/workspace/.pythonlibs/lib/python3.11/site-packages/telegram/ext/extbot.py", line 228, in get_updates
    updates = super().get_updates(
              ^^^^^^^^^^^^^^^^^^^^
  File "/home/runner/workspace/.pythonlibs/lib/python3.11/site-packages/telegram/bot.py", line 134, in decorator
    result = func(*args, **kwargs)
             ^^^^^^^^^^^^^^^^^^^^^
  File "/home/runner/workspace/.pythonlibs/lib/python3.11/site-packages/telegram/bot.py", line 3140, in get_updates
    self._post(
  File "/home/runner/workspace/.pythonlibs/lib/python3.11/site-packages/telegram/bot.py", line 299, in _post
    return self.request.post(
           ^^^^^^^^^^^^^^^^^^
  File "/home/runner/workspace/.pythonlibs/lib/python3.11/site-packages/telegram/utils/request.py", line 361, in post
    result = self._request_wrapper(
             ^^^^^^^^^^^^^^^^^^^^^^
  File "/home/runner/workspace/.pythonlibs/lib/python3.11/site-packages/telegram/utils/request.py", line 283, in _request_wrapper
    raise Conflict(message)

2025-04-05 07:34:11,842 - [ERROR] - azen_bot - error_handler:898 - Update None caused error Conflict: terminated by other getUpdates request; make sure that only one bot instance is running
Traceback:   File "/home/runner/workspace/.pythonlibs/lib/python3.11/site-packages/telegram/ext/updater.py", line 651, in _network_loop_retry
    if not action_cb():
           ^^^^^^^^^^^
  File "/home/runner/workspace/.pythonlibs/lib/python3.11/site-packages/telegram/ext/updater.py", line 602, in polling_action_cb
    updates = self.bot.get_updates(
              ^^^^^^^^^^^^^^^^^^^^^
  File "/home/runner/workspace/.pythonlibs/lib/python3.11/site-packages/telegram/ext/extbot.py", line 228, in get_updates
    updates = super().get_updates(
              ^^^^^^^^^^^^^^^^^^^^
  File "/home/runner/workspace/.pythonlibs/lib/python3.11/site-packages/telegram/bot.py", line 134, in decorator
    result = func(*args, **kwargs)
             ^^^^^^^^^^^^^^^^^^^^^
  File "/home/runner/workspace/.pythonlibs/lib/python3.11/site-packages/telegram/bot.py", line 3140, in get_updates
    self._post(
  File "/home/runner/workspace/.pythonlibs/lib/python3.11/site-packages/telegram/bot.py", line 299, in _post
    return self.request.post(
           ^^^^^^^^^^^^^^^^^^
  File "/home/runner/workspace/.pythonlibs/lib/python3.11/site-packages/telegram/utils/request.py", line 361, in post
    result = self._request_wrapper(
             ^^^^^^^^^^^^^^^^^^^^^^
  File "/home/runner/workspace/.pythonlibs/lib/python3.11/site-packages/telegram/utils/request.py", line 283, in _request_wrapper
    raise Conflict(message)

2025-04-05 07:34:29,136 - [ERROR] - azen_bot.errors - log_error:117 - ERROR_TYPE:GENERAL_ERROR - MESSAGE:Unexpected error: Conflict: terminated by other getUpdates request; make sure that only one bot instance is running - ADDITIONAL_INFO:Traceback:   File "/home/runner/workspace/.pythonlibs/lib/python3.11/site-packages/telegram/ext/updater.py", line 651, in _network_loop_retry
    if not action_cb():
           ^^^^^^^^^^^
  File "/home/runner/workspace/.pythonlibs/lib/python3.11/site-packages/telegram/ext/updater.py", line 602, in polling_action_cb
    updates = self.bot.get_updates(
              ^^^^^^^^^^^^^^^^^^^^^
  File "/home/runner/workspace/.pythonlibs/lib/python3.11/site-packages/telegram/ext/extbot.py", line 228, in get_updates
    updates = super().get_updates(
              ^^^^^^^^^^^^^^^^^^^^
  File "/home/runner/workspace/.pythonlibs/lib/python3.11/site-packages/telegram/bot.py", line 134, in decorator
    result = func(*args, **kwargs)
             ^^^^^^^^^^^^^^^^^^^^^
  File "/home/runner/workspace/.pythonlibs/lib/python3.11/site-packages/telegram/bot.py", line 3140, in get_updates
    self._post(
  File "/home/runner/workspace/.pythonlibs/lib/python3.11/site-packages/telegram/bot.py", line 299, in _post
    return self.request.post(
           ^^^^^^^^^^^^^^^^^^
  File "/home/runner/workspace/.pythonlibs/lib/python3.11/site-packages/telegram/utils/request.py", line 361, in post
    result = self._request_wrapper(
             ^^^^^^^^^^^^^^^^^^^^^^
  File "/home/runner/workspace/.pythonlibs/lib/python3.11/site-packages/telegram/utils/request.py", line 283, in _request_wrapper
    raise Conflict(message)

2025-04-05 07:34:29,137 - [ERROR] - azen_bot - error_handler:898 - Update None caused error Conflict: terminated by other getUpdates request; make sure that only one bot instance is running
Traceback:   File "/home/runner/workspace/.pythonlibs/lib/python3.11/site-packages/telegram/ext/updater.py", line 651, in _network_loop_retry
    if not action_cb():
           ^^^^^^^^^^^
  File "/home/runner/workspace/.pythonlibs/lib/python3.11/site-packages/telegram/ext/updater.py", line 602, in polling_action_cb
    updates = self.bot.get_updates(
              ^^^^^^^^^^^^^^^^^^^^^
  File "/home/runner/workspace/.pythonlibs/lib/python3.11/site-packages/telegram/ext/extbot.py", line 228, in get_updates
    updates = super().get_updates(
              ^^^^^^^^^^^^^^^^^^^^
  File "/home/runner/workspace/.pythonlibs/lib/python3.11/site-packages/telegram/bot.py", line 134, in decorator
    result = func(*args, **kwargs)
             ^^^^^^^^^^^^^^^^^^^^^
  File "/home/runner/workspace/.pythonlibs/lib/python3.11/site-packages/telegram/bot.py", line 3140, in get_updates
    self._post(
  File "/home/runner/workspace/.pythonlibs/lib/python3.11/site-packages/telegram/bot.py", line 299, in _post
    return self.request.post(
           ^^^^^^^^^^^^^^^^^^
  File "/home/runner/workspace/.pythonlibs/lib/python3.11/site-packages/telegram/utils/request.py", line 361, in post
    result = self._request_wrapper(
             ^^^^^^^^^^^^^^^^^^^^^^
  File "/home/runner/workspace/.pythonlibs/lib/python3.11/site-packages/telegram/utils/request.py", line 283, in _request_wrapper
    raise Conflict(message)

2025-04-05 07:34:54,911 - [ERROR] - azen_bot.errors - log_error:117 - ERROR_TYPE:GENERAL_ERROR - MESSAGE:Unexpected error: Conflict: terminated by other getUpdates request; make sure that only one bot instance is running - ADDITIONAL_INFO:Traceback:   File "/home/runner/workspace/.pythonlibs/lib/python3.11/site-packages/telegram/ext/updater.py", line 651, in _network_loop_retry
    if not action_cb():
           ^^^^^^^^^^^
  File "/home/runner/workspace/.pythonlibs/lib/python3.11/site-packages/telegram/ext/updater.py", line 602, in polling_action_cb
    updates = self.bot.get_updates(
              ^^^^^^^^^^^^^^^^^^^^^
  File "/home/runner/workspace/.pythonlibs/lib/python3.11/site-packages/telegram/ext/extbot.py", line 228, in get_updates
    updates = super().get_updates(
              ^^^^^^^^^^^^^^^^^^^^
  File "/home/runner/workspace/.pythonlibs/lib/python3.11/site-packages/telegram/bot.py", line 134, in decorator
    result = func(*args, **kwargs)
             ^^^^^^^^^^^^^^^^^^^^^
  File "/home/runner/workspace/.pythonlibs/lib/python3.11/site-packages/telegram/bot.py", line 3140, in get_updates
    self._post(
  File "/home/runner/workspace/.pythonlibs/lib/python3.11/site-packages/telegram/bot.py", line 299, in _post
    return self.request.post(
           ^^^^^^^^^^^^^^^^^^
  File "/home/runner/workspace/.pythonlibs/lib/python3.11/site-packages/telegram/utils/request.py", line 361, in post
    result = self._request_wrapper(
             ^^^^^^^^^^^^^^^^^^^^^^
  File "/home/runner/workspace/.pythonlibs/lib/python3.11/site-packages/telegram/utils/request.py", line 283, in _request_wrapper
    raise Conflict(message)

2025-04-05 07:34:54,912 - [ERROR] - azen_bot - error_handler:898 - Update None caused error Conflict: terminated by other getUpdates request; make sure that only one bot instance is running
Traceback:   File "/home/runner/workspace/.pythonlibs/lib/python3.11/site-packages/telegram/ext/updater.py", line 651, in _network_loop_retry
    if not action_cb():
           ^^^^^^^^^^^
  File "/home/runner/workspace/.pythonlibs/lib/python3.11/site-packages/telegram/ext/updater.py", line 602, in polling_action_cb
    updates = self.bot.get_updates(
              ^^^^^^^^^^^^^^^^^^^^^
  File "/home/runner/workspace/.pythonlibs/lib/python3.11/site-packages/telegram/ext/extbot.py", line 228, in get_updates
    updates = super().get_updates(
              ^^^^^^^^^^^^^^^^^^^^
  File "/home/runner/workspace/.pythonlibs/lib/python3.11/site-packages/telegram/bot.py", line 134, in decorator
    result = func(*args, **kwargs)
             ^^^^^^^^^^^^^^^^^^^^^
  File "/home/runner/workspace/.pythonlibs/lib/python3.11/site-packages/telegram/bot.py", line 3140, in get_updates
    self._post(
  File "/home/runner/workspace/.pythonlibs/lib/python3.11/site-packages/telegram/bot.py", line 299, in _post
    return self.request.post(
           ^^^^^^^^^^^^^^^^^^
  File "/home/runner/workspace/.pythonlibs/lib/python3.11/site-packages/telegram/utils/request.py", line 361, in post
    result = self._request_wrapper(
             ^^^^^^^^^^^^^^^^^^^^^^
  File "/home/runner/workspace/.pythonlibs/lib/python3.11/site-packages/telegram/utils/request.py", line 283, in _request_wrapper
    raise Conflict(message)

2025-04-05 07:34:59,054 - [ERROR] - azen_bot.errors - log_error:117 - ERROR_TYPE:GENERAL_ERROR - MESSAGE:Unexpected error: Conflict: terminated by other getUpdates request; make sure that only one bot instance is running - ADDITIONAL_INFO:Traceback:   File "/home/runner/workspace/.pythonlibs/lib/python3.11/site-packages/telegram/ext/updater.py", line 651, in _network_loop_retry
    if not action_cb():
           ^^^^^^^^^^^
  File "/home/runner/workspace/.pythonlibs/lib/python3.11/site-packages/telegram/ext/updater.py", line 602, in polling_action_cb
    updates = self.bot.get_updates(
              ^^^^^^^^^^^^^^^^^^^^^
  File "/home/runner/workspace/.pythonlibs/lib/python3.11/site-packages/telegram/ext/extbot.py", line 228, in get_updates
    updates = super().get_updates(
              ^^^^^^^^^^^^^^^^^^^^
  File "/home/runner/workspace/.pythonlibs/lib/python3.11/site-packages/telegram/bot.py", line 134, in decorator
    result = func(*args, **kwargs)
             ^^^^^^^^^^^^^^^^^^^^^
  File "/home/runner/workspace/.pythonlibs/lib/python3.11/site-packages/telegram/bot.py", line 3140, in get_updates
    self._post(
  File "/home/runner/workspace/.pythonlibs/lib/python3.11/site-packages/telegram/bot.py", line 299, in _post
    return self.request.post(
           ^^^^^^^^^^^^^^^^^^
  File "/home/runner/workspace/.pythonlibs/lib/python3.11/site-packages/telegram/utils/request.py", line 361, in post
    result = self._request_wrapper(
             ^^^^^^^^^^^^^^^^^^^^^^
  File "/home/runner/workspace/.pythonlibs/lib/python3.11/site-packages/telegram/utils/request.py", line 283, in _request_wrapper
    raise Conflict(message)

2025-04-05 07:34:59,055 - [ERROR] - azen_bot - error_handler:898 - Update None caused error Conflict: terminated by other getUpdates request; make sure that only one bot instance is running
Traceback:   File "/home/runner/workspace/.pythonlibs/lib/python3.11/site-packages/telegram/ext/updater.py", line 651, in _network_loop_retry
    if not action_cb():
           ^^^^^^^^^^^
  File "/home/runner/workspace/.pythonlibs/lib/python3.11/site-packages/telegram/ext/updater.py", line 602, in polling_action_cb
    updates = self.bot.get_updates(
              ^^^^^^^^^^^^^^^^^^^^^
  File "/home/runner/workspace/.pythonlibs/lib/python3.11/site-packages/telegram/ext/extbot.py", line 228, in get_updates
    updates = super().get_updates(
              ^^^^^^^^^^^^^^^^^^^^
  File "/home/runner/workspace/.pythonlibs/lib/python3.11/site-packages/telegram/bot.py", line 134, in decorator
    result = func(*args, **kwargs)
             ^^^^^^^^^^^^^^^^^^^^^
  File "/home/runner/workspace/.pythonlibs/lib/python3.11/site-packages/telegram/bot.py", line 3140, in get_updates
    self._post(
  File "/home/runner/workspace/.pythonlibs/lib/python3.11/site-packages/telegram/bot.py", line 299, in _post
    return self.request.post(
           ^^^^^^^^^^^^^^^^^^
  File "/home/runner/workspace/.pythonlibs/lib/python3.11/site-packages/telegram/utils/request.py", line 361, in post
    result = self._request_wrapper(
             ^^^^^^^^^^^^^^^^^^^^^^
  File "/home/runner/workspace/.pythonlibs/lib/python3.11/site-packages/telegram/utils/request.py", line 283, in _request_wrapper
    raise Conflict(message)

2025-04-05 07:35:37,641 - [ERROR] - azen_bot.errors - log_error:117 - ERROR_TYPE:GENERAL_ERROR - MESSAGE:Unexpected error: Conflict: terminated by other getUpdates request; make sure that only one bot instance is running - ADDITIONAL_INFO:Traceback:   File "/home/runner/workspace/.pythonlibs/lib/python3.11/site-packages/telegram/ext/updater.py", line 651, in _network_loop_retry
    if not action_cb():
           ^^^^^^^^^^^
  File "/home/runner/workspace/.pythonlibs/lib/python3.11/site-packages/telegram/ext/updater.py", line 602, in polling_action_cb
    updates = self.bot.get_updates(
              ^^^^^^^^^^^^^^^^^^^^^
  File "/home/runner/workspace/.pythonlibs/lib/python3.11/site-packages/telegram/ext/extbot.py", line 228, in get_updates
    updates = super().get_updates(
              ^^^^^^^^^^^^^^^^^^^^
  File "/home/runner/workspace/.pythonlibs/lib/python3.11/site-packages/telegram/bot.py", line 134, in decorator
    result = func(*args, **kwargs)
             ^^^^^^^^^^^^^^^^^^^^^
  File "/home/runner/workspace/.pythonlibs/lib/python3.11/site-packages/telegram/bot.py", line 3140, in get_updates
    self._post(
  File "/home/runner/workspace/.pythonlibs/lib/python3.11/site-packages/telegram/bot.py", line 299, in _post
    return self.request.post(
           ^^^^^^^^^^^^^^^^^^
  File "/home/runner/workspace/.pythonlibs/lib/python3.11/site-packages/telegram/utils/request.py", line 361, in post
    result = self._request_wrapper(
             ^^^^^^^^^^^^^^^^^^^^^^
  File "/home/runner/workspace/.pythonlibs/lib/python3.11/site-packages/telegram/utils/request.py", line 283, in _request_wrapper
    raise Conflict(message)

2025-04-05 07:35:37,642 - [ERROR] - azen_bot - error_handler:898 - Update None caused error Conflict: terminated by other getUpdates request; make sure that only one bot instance is running
Traceback:   File "/home/runner/workspace/.pythonlibs/lib/python3.11/site-packages/telegram/ext/updater.py", line 651, in _network_loop_retry
    if not action_cb():
           ^^^^^^^^^^^
  File "/home/runner/workspace/.pythonlibs/lib/python3.11/site-packages/telegram/ext/updater.py", line 602, in polling_action_cb
    updates = self.bot.get_updates(
              ^^^^^^^^^^^^^^^^^^^^^
  File "/home/runner/workspace/.pythonlibs/lib/python3.11/site-packages/telegram/ext/extbot.py", line 228, in get_updates
    updates = super().get_updates(
              ^^^^^^^^^^^^^^^^^^^^
  File "/home/runner/workspace/.pythonlibs/lib/python3.11/site-packages/telegram/bot.py", line 134, in decorator
    result = func(*args, **kwargs)
             ^^^^^^^^^^^^^^^^^^^^^
  File "/home/runner/workspace/.pythonlibs/lib/python3.11/site-packages/telegram/bot.py", line 3140, in get_updates
    self._post(
  File "/home/runner/workspace/.pythonlibs/lib/python3.11/site-packages/telegram/bot.py", line 299, in _post
    return self.request.post(
           ^^^^^^^^^^^^^^^^^^
  File "/home/runner/workspace/.pythonlibs/lib/python3.11/site-packages/telegram/utils/request.py", line 361, in post
    result = self._request_wrapper(
             ^^^^^^^^^^^^^^^^^^^^^^
  File "/home/runner/workspace/.pythonlibs/lib/python3.11/site-packages/telegram/utils/request.py", line 283, in _request_wrapper
    raise Conflict(message)

2025-04-05 07:35:41,784 - [ERROR] - azen_bot.errors - log_error:117 - ERROR_TYPE:GENERAL_ERROR - MESSAGE:Unexpected error: Conflict: terminated by other getUpdates request; make sure that only one bot instance is running - ADDITIONAL_INFO:Traceback:   File "/home/runner/workspace/.pythonlibs/lib/python3.11/site-packages/telegram/ext/updater.py", line 651, in _network_loop_retry
    if not action_cb():
           ^^^^^^^^^^^
  File "/home/runner/workspace/.pythonlibs/lib/python3.11/site-packages/telegram/ext/updater.py", line 602, in polling_action_cb
    updates = self.bot.get_updates(
              ^^^^^^^^^^^^^^^^^^^^^
  File "/home/runner/workspace/.pythonlibs/lib/python3.11/site-packages/telegram/ext/extbot.py", line 228, in get_updates
    updates = super().get_updates(
              ^^^^^^^^^^^^^^^^^^^^
  File "/home/runner/workspace/.pythonlibs/lib/python3.11/site-packages/telegram/bot.py", line 134, in decorator
    result = func(*args, **kwargs)
             ^^^^^^^^^^^^^^^^^^^^^
  File "/home/runner/workspace/.pythonlibs/lib/python3.11/site-packages/telegram/bot.py", line 3140, in get_updates
    self._post(
  File "/home/runner/workspace/.pythonlibs/lib/python3.11/site-packages/telegram/bot.py", line 299, in _post
    return self.request.post(
           ^^^^^^^^^^^^^^^^^^
  File "/home/runner/workspace/.pythonlibs/lib/python3.11/site-packages/telegram/utils/request.py", line 361, in post
    result = self._request_wrapper(
             ^^^^^^^^^^^^^^^^^^^^^^
  File "/home/runner/workspace/.pythonlibs/lib/python3.11/site-packages/telegram/utils/request.py", line 283, in _request_wrapper
    raise Conflict(message)

2025-04-05 07:35:41,784 - [ERROR] - azen_bot - error_handler:898 - Update None caused error Conflict: terminated by other getUpdates request; make sure that only one bot instance is running
Traceback:   File "/home/runner/workspace/.pythonlibs/lib/python3.11/site-packages/telegram/ext/updater.py", line 651, in _network_loop_retry
    if not action_cb():
           ^^^^^^^^^^^
  File "/home/runner/workspace/.pythonlibs/lib/python3.11/site-packages/telegram/ext/updater.py", line 602, in polling_action_cb
    updates = self.bot.get_updates(
              ^^^^^^^^^^^^^^^^^^^^^
  File "/home/runner/workspace/.pythonlibs/lib/python3.11/site-packages/telegram/ext/extbot.py", line 228, in get_updates
    updates = super().get_updates(
              ^^^^^^^^^^^^^^^^^^^^
  File "/home/runner/workspace/.pythonlibs/lib/python3.11/site-packages/telegram/bot.py", line 134, in decorator
    result = func(*args, **kwargs)
             ^^^^^^^^^^^^^^^^^^^^^
  File "/home/runner/workspace/.pythonlibs/lib/python3.11/site-packages/telegram/bot.py", line 3140, in get_updates
    self._post(
  File "/home/runner/workspace/.pythonlibs/lib/python3.11/site-packages/telegram/bot.py", line 299, in _post
    return self.request.post(
           ^^^^^^^^^^^^^^^^^^
  File "/home/runner/workspace/.pythonlibs/lib/python3.11/site-packages/telegram/utils/request.py", line 361, in post
    result = self._request_wrapper(
             ^^^^^^^^^^^^^^^^^^^^^^
  File "/home/runner/workspace/.pythonlibs/lib/python3.11/site-packages/telegram/utils/request.py", line 283, in _request_wrapper
    raise Conflict(message)

2025-04-05 07:36:11,929 - [ERROR] - azen_bot.errors - log_error:117 - ERROR_TYPE:GENERAL_ERROR - MESSAGE:Unexpected error: Conflict: terminated by other getUpdates request; make sure that only one bot instance is running - ADDITIONAL_INFO:Traceback:   File "/home/runner/workspace/.pythonlibs/lib/python3.11/site-packages/telegram/ext/updater.py", line 651, in _network_loop_retry
    if not action_cb():
           ^^^^^^^^^^^
  File "/home/runner/workspace/.pythonlibs/lib/python3.11/site-packages/telegram/ext/updater.py", line 602, in polling_action_cb
    updates = self.bot.get_updates(
              ^^^^^^^^^^^^^^^^^^^^^
  File "/home/runner/workspace/.pythonlibs/lib/python3.11/site-packages/telegram/ext/extbot.py", line 228, in get_updates
    updates = super().get_updates(
              ^^^^^^^^^^^^^^^^^^^^
  File "/home/runner/workspace/.pythonlibs/lib/python3.11/site-packages/telegram/bot.py", line 134, in decorator
    result = func(*args, **kwargs)
             ^^^^^^^^^^^^^^^^^^^^^
  File "/home/runner/workspace/.pythonlibs/lib/python3.11/site-packages/telegram/bot.py", line 3140, in get_updates
    self._post(
  File "/home/runner/workspace/.pythonlibs/lib/python3.11/site-packages/telegram/bot.py", line 299, in _post
    return self.request.post(
           ^^^^^^^^^^^^^^^^^^
  File "/home/runner/workspace/.pythonlibs/lib/python3.11/site-packages/telegram/utils/request.py", line 361, in post
    result = self._request_wrapper(
             ^^^^^^^^^^^^^^^^^^^^^^
  File "/home/runner/workspace/.pythonlibs/lib/python3.11/site-packages/telegram/utils/request.py", line 283, in _request_wrapper
    raise Conflict(message)

2025-04-05 07:36:11,930 - [ERROR] - azen_bot - error_handler:898 - Update None caused error Conflict: terminated by other getUpdates request; make sure that only one bot instance is running
Traceback:   File "/home/runner/workspace/.pythonlibs/lib/python3.11/site-packages/telegram/ext/updater.py", line 651, in _network_loop_retry
    if not action_cb():
           ^^^^^^^^^^^
  File "/home/runner/workspace/.pythonlibs/lib/python3.11/site-packages/telegram/ext/updater.py", line 602, in polling_action_cb
    updates = self.bot.get_updates(
              ^^^^^^^^^^^^^^^^^^^^^
  File "/home/runner/workspace/.pythonlibs/lib/python3.11/site-packages/telegram/ext/extbot.py", line 228, in get_updates
    updates = super().get_updates(
              ^^^^^^^^^^^^^^^^^^^^
  File "/home/runner/workspace/.pythonlibs/lib/python3.11/site-packages/telegram/bot.py", line 134, in decorator
    result = func(*args, **kwargs)
             ^^^^^^^^^^^^^^^^^^^^^
  File "/home/runner/workspace/.pythonlibs/lib/python3.11/site-packages/telegram/bot.py", line 3140, in get_updates
    self._post(
  File "/home/runner/workspace/.pythonlibs/lib/python3.11/site-packages/telegram/bot.py", line 299, in _post
    return self.request.post(
           ^^^^^^^^^^^^^^^^^^
  File "/home/runner/workspace/.pythonlibs/lib/python3.11/site-packages/telegram/utils/request.py", line 361, in post
    result = self._request_wrapper(
             ^^^^^^^^^^^^^^^^^^^^^^
  File "/home/runner/workspace/.pythonlibs/lib/python3.11/site-packages/telegram/utils/request.py", line 283, in _request_wrapper
    raise Conflict(message)

2025-04-05 07:36:16,073 - [ERROR] - azen_bot.errors - log_error:117 - ERROR_TYPE:GENERAL_ERROR - MESSAGE:Unexpected error: Conflict: terminated by other getUpdates request; make sure that only one bot instance is running - ADDITIONAL_INFO:Traceback:   File "/home/runner/workspace/.pythonlibs/lib/python3.11/site-packages/telegram/ext/updater.py", line 651, in _network_loop_retry
    if not action_cb():
           ^^^^^^^^^^^
  File "/home/runner/workspace/.pythonlibs/lib/python3.11/site-packages/telegram/ext/updater.py", line 602, in polling_action_cb
    updates = self.bot.get_updates(
              ^^^^^^^^^^^^^^^^^^^^^
  File "/home/runner/workspace/.pythonlibs/lib/python3.11/site-packages/telegram/ext/extbot.py", line 228, in get_updates
    updates = super().get_updates(
              ^^^^^^^^^^^^^^^^^^^^
  File "/home/runner/workspace/.pythonlibs/lib/python3.11/site-packages/telegram/bot.py", line 134, in decorator
    result = func(*args, **kwargs)
             ^^^^^^^^^^^^^^^^^^^^^
  File "/home/runner/workspace/.pythonlibs/lib/python3.11/site-packages/telegram/bot.py", line 3140, in get_updates
    self._post(
  File "/home/runner/workspace/.pythonlibs/lib/python3.11/site-packages/telegram/bot.py", line 299, in _post
    return self.request.post(
           ^^^^^^^^^^^^^^^^^^
  File "/home/runner/workspace/.pythonlibs/lib/python3.11/site-packages/telegram/utils/request.py", line 361, in post
    result = self._request_wrapper(
             ^^^^^^^^^^^^^^^^^^^^^^
  File "/home/runner/workspace/.pythonlibs/lib/python3.11/site-packages/telegram/utils/request.py", line 283, in _request_wrapper
    raise Conflict(message)

2025-04-05 07:36:16,073 - [ERROR] - azen_bot - error_handler:898 - Update None caused error Conflict: terminated by other getUpdates request; make sure that only one bot instance is running
Traceback:   File "/home/runner/workspace/.pythonlibs/lib/python3.11/site-packages/telegram/ext/updater.py", line 651, in _network_loop_retry
    if not action_cb():
           ^^^^^^^^^^^
  File "/home/runner/workspace/.pythonlibs/lib/python3.11/site-packages/telegram/ext/updater.py", line 602, in polling_action_cb
    updates = self.bot.get_updates(
              ^^^^^^^^^^^^^^^^^^^^^
  File "/home/runner/workspace/.pythonlibs/lib/python3.11/site-packages/telegram/ext/extbot.py", line 228, in get_updates
    updates = super().get_updates(
              ^^^^^^^^^^^^^^^^^^^^
  File "/home/runner/workspace/.pythonlibs/lib/python3.11/site-packages/telegram/bot.py", line 134, in decorator
    result = func(*args, **kwargs)
             ^^^^^^^^^^^^^^^^^^^^^
  File "/home/runner/workspace/.pythonlibs/lib/python3.11/site-packages/telegram/bot.py", line 3140, in get_updates
    self._post(
  File "/home/runner/workspace/.pythonlibs/lib/python3.11/site-packages/telegram/bot.py", line 299, in _post
    return self.request.post(
           ^^^^^^^^^^^^^^^^^^
  File "/home/runner/workspace/.pythonlibs/lib/python3.11/site-packages/telegram/utils/request.py", line 361, in post
    result = self._request_wrapper(
             ^^^^^^^^^^^^^^^^^^^^^^
  File "/home/runner/workspace/.pythonlibs/lib/python3.11/site-packages/telegram/utils/request.py", line 283, in _request_wrapper
    raise Conflict(message)

2025-04-05 07:36:46,217 - [ERROR] - azen_bot.errors - log_error:117 - ERROR_TYPE:GENERAL_ERROR - MESSAGE:Unexpected error: Conflict: terminated by other getUpdates request; make sure that only one bot instance is running - ADDITIONAL_INFO:Traceback:   File "/home/runner/workspace/.pythonlibs/lib/python3.11/site-packages/telegram/ext/updater.py", line 651, in _network_loop_retry
    if not action_cb():
           ^^^^^^^^^^^
  File "/home/runner/workspace/.pythonlibs/lib/python3.11/site-packages/telegram/ext/updater.py", line 602, in polling_action_cb
    updates = self.bot.get_updates(
              ^^^^^^^^^^^^^^^^^^^^^
  File "/home/runner/workspace/.pythonlibs/lib/python3.11/site-packages/telegram/ext/extbot.py", line 228, in get_updates
    updates = super().get_updates(
              ^^^^^^^^^^^^^^^^^^^^
  File "/home/runner/workspace/.pythonlibs/lib/python3.11/site-packages/telegram/bot.py", line 134, in decorator
    result = func(*args, **kwargs)
             ^^^^^^^^^^^^^^^^^^^^^
  File "/home/runner/workspace/.pythonlibs/lib/python3.11/site-packages/telegram/bot.py", line 3140, in get_updates
    self._post(
  File "/home/runner/workspace/.pythonlibs/lib/python3.11/site-packages/telegram/bot.py", line 299, in _post
    return self.request.post(
           ^^^^^^^^^^^^^^^^^^
  File "/home/runner/workspace/.pythonlibs/lib/python3.11/site-packages/telegram/utils/request.py", line 361, in post
    result = self._request_wrapper(
             ^^^^^^^^^^^^^^^^^^^^^^
  File "/home/runner/workspace/.pythonlibs/lib/python3.11/site-packages/telegram/utils/request.py", line 283, in _request_wrapper
    raise Conflict(message)

2025-04-05 07:36:46,217 - [ERROR] - azen_bot - error_handler:898 - Update None caused error Conflict: terminated by other getUpdates request; make sure that only one bot instance is running
Traceback:   File "/home/runner/workspace/.pythonlibs/lib/python3.11/site-packages/telegram/ext/updater.py", line 651, in _network_loop_retry
    if not action_cb():
           ^^^^^^^^^^^
  File "/home/runner/workspace/.pythonlibs/lib/python3.11/site-packages/telegram/ext/updater.py", line 602, in polling_action_cb
    updates = self.bot.get_updates(
              ^^^^^^^^^^^^^^^^^^^^^
  File "/home/runner/workspace/.pythonlibs/lib/python3.11/site-packages/telegram/ext/extbot.py", line 228, in get_updates
    updates = super().get_updates(
              ^^^^^^^^^^^^^^^^^^^^
  File "/home/runner/workspace/.pythonlibs/lib/python3.11/site-packages/telegram/bot.py", line 134, in decorator
    result = func(*args, **kwargs)
             ^^^^^^^^^^^^^^^^^^^^^
  File "/home/runner/workspace/.pythonlibs/lib/python3.11/site-packages/telegram/bot.py", line 3140, in get_updates
    self._post(
  File "/home/runner/workspace/.pythonlibs/lib/python3.11/site-packages/telegram/bot.py", line 299, in _post
    return self.request.post(
           ^^^^^^^^^^^^^^^^^^
  File "/home/runner/workspace/.pythonlibs/lib/python3.11/site-packages/telegram/utils/request.py", line 361, in post
    result = self._request_wrapper(
             ^^^^^^^^^^^^^^^^^^^^^^
  File "/home/runner/workspace/.pythonlibs/lib/python3.11/site-packages/telegram/utils/request.py", line 283, in _request_wrapper
    raise Conflict(message)

2025-04-05 07:36:50,360 - [ERROR] - azen_bot.errors - log_error:117 - ERROR_TYPE:GENERAL_ERROR - MESSAGE:Unexpected error: Conflict: terminated by other getUpdates request; make sure that only one bot instance is running - ADDITIONAL_INFO:Traceback:   File "/home/runner/workspace/.pythonlibs/lib/python3.11/site-packages/telegram/ext/updater.py", line 651, in _network_loop_retry
    if not action_cb():
           ^^^^^^^^^^^
  File "/home/runner/workspace/.pythonlibs/lib/python3.11/site-packages/telegram/ext/updater.py", line 602, in polling_action_cb
    updates = self.bot.get_updates(
              ^^^^^^^^^^^^^^^^^^^^^
  File "/home/runner/workspace/.pythonlibs/lib/python3.11/site-packages/telegram/ext/extbot.py", line 228, in get_updates
    updates = super().get_updates(
              ^^^^^^^^^^^^^^^^^^^^
  File "/home/runner/workspace/.pythonlibs/lib/python3.11/site-packages/telegram/bot.py", line 134, in decorator
    result = func(*args, **kwargs)
             ^^^^^^^^^^^^^^^^^^^^^
  File "/home/runner/workspace/.pythonlibs/lib/python3.11/site-packages/telegram/bot.py", line 3140, in get_updates
    self._post(
  File "/home/runner/workspace/.pythonlibs/lib/python3.11/site-packages/telegram/bot.py", line 299, in _post
    return self.request.post(
           ^^^^^^^^^^^^^^^^^^
  File "/home/runner/workspace/.pythonlibs/lib/python3.11/site-packages/telegram/utils/request.py", line 361, in post
    result = self._request_wrapper(
             ^^^^^^^^^^^^^^^^^^^^^^
  File "/home/runner/workspace/.pythonlibs/lib/python3.11/site-packages/telegram/utils/request.py", line 283, in _request_wrapper
    raise Conflict(message)

2025-04-05 07:36:50,362 - [ERROR] - azen_bot - error_handler:898 - Update None caused error Conflict: terminated by other getUpdates request; make sure that only one bot instance is running
Traceback:   File "/home/runner/workspace/.pythonlibs/lib/python3.11/site-packages/telegram/ext/updater.py", line 651, in _network_loop_retry
    if not action_cb():
           ^^^^^^^^^^^
  File "/home/runner/workspace/.pythonlibs/lib/python3.11/site-packages/telegram/ext/updater.py", line 602, in polling_action_cb
    updates = self.bot.get_updates(
              ^^^^^^^^^^^^^^^^^^^^^
  File "/home/runner/workspace/.pythonlibs/lib/python3.11/site-packages/telegram/ext/extbot.py", line 228, in get_updates
    updates = super().get_updates(
              ^^^^^^^^^^^^^^^^^^^^
  File "/home/runner/workspace/.pythonlibs/lib/python3.11/site-packages/telegram/bot.py", line 134, in decorator
    result = func(*args, **kwargs)
             ^^^^^^^^^^^^^^^^^^^^^
  File "/home/runner/workspace/.pythonlibs/lib/python3.11/site-packages/telegram/bot.py", line 3140, in get_updates
    self._post(
  File "/home/runner/workspace/.pythonlibs/lib/python3.11/site-packages/telegram/bot.py", line 299, in _post
    return self.request.post(
           ^^^^^^^^^^^^^^^^^^
  File "/home/runner/workspace/.pythonlibs/lib/python3.11/site-packages/telegram/utils/request.py", line 361, in post
    result = self._request_wrapper(
             ^^^^^^^^^^^^^^^^^^^^^^
  File "/home/runner/workspace/.pythonlibs/lib/python3.11/site-packages/telegram/utils/request.py", line 283, in _request_wrapper
    raise Conflict(message)

